Workbook

Sheet Shock_quarterly
A1: Year | B1: Quarter | C1: Shocks | D1: Threshold | E1: Shocks 2 | F1: Threshold2
A2: 2024 | B2: 4
A3: 2024 | B3: 3 | C3: Environmental/Biological | D3: 2
A4: 2024 | B4: 2 | C4: Environmental/Biological | D4: 2
A5: 2024 | B5: 1
A6: 2023 | B6: 4
A7: 2023 | B7: 3
A8: 2023 | B8: 2 | C8: Political/Policy | D8: 2
A9: 2023 | B9: 1
A10: 2022 | B10: 4
A11: 2022 | B11: 3 | C11: Economic | D11: 2
A12: 2022 | B12: 2 | C12: Economic | D12: 2
A13: 2022 | B13: 1
A14: 2021 | B14: 4
A15: 2021 | B15: 3 | C15: Economic | D15: 3
A16: 2021 | B16: 2 | C16: Economic | D16: 2
A17: 2021 | B17: 1 | C17: Economic | D17: 2
A18: 2020 | B18: 4 | C18: Environmental/Biological | D18: 1
A19: 2020 | B19: 3 | C19: Political/Policy | D19: 1
A20: 2020 | B20: 2 | C20: Political/Policy | D20: 2
A21: 2020 | B21: 1
A22: 2019 | B22: 4
A23: 2019 | B23: 3 | C23: Environmental/Biological | D23: 1 | E23: Environmental/Biological | F23: 1
A24: 2019 | B24: 2 | C24: Environmental/Biological | D24: 2
A25: 2019 | B25: 1
A26: 2018 | B26: 4
A27: 2018 | B27: 3 | C27: Economic | D27: 2
A28: 2018 | B28: 2
A29: 2018 | B29: 1 | C29: Political/Policy | D29: 2
A30: 2017 | B30: 4
A31: 2017 | B31: 3
A32: 2017 | B32: 2
A33: 2017 | B33: 1
A34: 2016 | B34: 4 | C34: Environmental/Biological | D34: 1
A35: 2016 | B35: 3
A36: 2016 | B36: 2 | C36: Environmental/Biological | D36: 2
A37: 2016 | B37: 1 | C37: Environmental/Biological | D37: 2
A38: 2015 | B38: 4 | C38: Environmental/Biological | D38: 2
A39: 2015 | B39: 3
A40: 2015 | B40: 2 | C40: Political/Policy | D40: 2
...

Sheet Shock event mapping
A1: Year | B1: Quarter | C1: Month | D1: Event | E1: Shocks | F1: Impact to HN FS | G1: Threshold
A2: 2014 | B2: 4 | D2: Amended Constitution 118/2014 on rearranging and innovating agro-forestry companies. | E2: Political/Policy | F2: Agricultural restructuring affected the supply chains of agricultural products for Hanoi | G2: 2
A3: 2014 | B3: 4 | D3: Floods in the North due to prolonged rain. | E3: Environmental/Biological | F3: Flooded fields, reduced yields of rice and vegetables; disrupted urban food transportation | G3: 1
A4: 2015 | B4: 2 | D4: Supermarkets in Hanoi sell vegetables with no origin documentation, causing consumer reaction. | E4: Political/Policy | F4: Increased food safety concerns, reduced consumption at traditional markets and supermarkets; led to stronger food safety control | G4: 2
A5: 2015 | B5: 4 | D5: Beginning of El Niño drought. | E5: Environmental/Biological | F5: Began to impact food supply from main production areas | G5: 2
A6: 2016 | B6: 1 | D6: El Niño drought peaks. | E6: Environmental/Biological | F6: Loss of 1.2 million tons of rice nationwide; rice exports decreased by 4.45%, severely affecting food supply to Hanoi | G6: 2
A7: 2016 | B7: 2 | D7: Severe drought in 2016 in the Mekong River Delta. | E7: Environmental/Biological | F7: Reduced rice yield – threatening rice supply, raising prices in Hanoi; downstream farmers heavily affected | G7: 2
A8: 2016 | B8: 4 | D8: Drought, high temperatures in suburban vegetable growing areas. | E8: Environmental/Biological | F8: Water shortage for irrigation, reduced vegetable yields, rising vegetable prices; affected daily meals of Hanoi residents | G8: 1
A9: 2018 | B9: 1 | D9: CPTPP comes into effect. | E9: Political/Policy | F9: Changes in agricultural import-export structures affected the price and quality of food in Hanoi | G9: 2
A10: 2018 | B10: 3 | D10: Fluctuation in global fuel prices & transportation costs. | E10: Economic | F10: Transportation costs surged → food prices increased, disrupted the supply chain from Mekong Delta to Hanoi | G10: 2
A11: 2019 | B11: 2 | D11: Outbreak of African Swine Fever (ASF) in Long Bien, spreading throughout Hanoi. | E11: Environmental/Biological | F11: Approximately 495,000 pigs culled (26.5% of total herd), ~35% of pig farming households affected → pork shortages, prices surged, pork supply chain disrupted | G11: 2
A12: 2019 | B12: 3 | D12: Outbreak of African Swine Fever (ASF) in Long Bien, spreading throughout Hanoi. | E12: Environmental/Biological | F12: Approximately 495,000 pigs culled (26.5% of total herd), ~35% of pig farming households affected → pork shortages, prices surged, pork supply chain disrupted | G12: 1
A13: 2019 | B13: 3 | C13: 8 | D13: Typhoon Wipha (No. 3). | E13: Environmental/Biological | F13: Heavy rain and flooding in Hanoi affected traditional markets and food transportation | G13: 1
A14: 2020 | B14: 2 | D14: COVID-19 and social distancing affect trade, markets & media. | E14: Political/Policy | F14: Distribution of vegetables and food disrupted; increased pressure on logistics and retail systems | G14: 2
A15: 2020 | B15: 3 | D15: EVFTA agreement comes into effect. | E15: Political/Policy | F15: Vietnam opened EU market access for agricultural products, boosting exports, which affected domestic food prices | G15: 1
A16: 2020 | B16: 4 | D16: Tropical Storm Linfa/Goni | E16: Environmental/Biological | F16: primarily affected the Central region, it still disrupted the supply chains of vegetables and fish - especially when Hanoi shifted from fast to slower domestic sources; this could lead to short-term shortages and price increases. | G16: 1
A17: 2021 | B17: 1 | D17: Suez Canal obstruction (Ever Given). | E17: Economic | F17: Global logistics disruptions delayed food imports, increasing shipping costs | G17: 2
A18: 2021 | B18: 2 | D18: High inflation, rising input prices (fertilizer, labor). | E18: Economic | F18: Agricultural product prices rose, farming costs increased, affecting retail prices | G18: 2
A19: 2021 | B19: 3 | D19: COVID-19 | E19: Economic | F19: Inflation remained low due to economic support, but food supply chains were still disrupted | G19: 3
A20: 2022 | B20: 2 | D20: Russia-Ukraine War: disruption of agricultural and energy supply chains. | E20: Economic | F20: Fertilizer prices increased by ~60–80%, animal feed + wheat + corn prices rose by 10–20%, pushing up production and farming costs in Hanoi | G20: 2
A21: 2022 | B21: 3 | D21: Russia-Ukraine War: disruption of agricultural and energy supply chains. | E21: Economic | F21: Fertilizer prices increased by ~60–80%, animal feed + wheat + corn prices rose by 10–20%, pushing up production and farming costs in Hanoi | G21: 2
A22: 2023 | B22: 2 | D22: Change in food safety policy, increased post-auditing control. | E22: Political/Policy | F22: Small-scale farmers and processors faced compliance pressure; rising costs; many local products struggled to access formal markets | G22: 2
A23: 2024 | B23: 2 | D23: Record drought in 2024 in Mekong River Delta - causing water scarcity. | E23: Environmental/Biological | F23: Decline in supply of rice, vegetables, and fish; raw material prices surged, affecting local markets and school canteens in Hanoi | G23: 2
A24: 2024 | B24: 3 | D24: Super Typhoon Yagi (No. 3) makes landfall in the North, causing flooding in Hanoi. | E24: Environmental/Biological | F24: 18,000 households flooded; 84,000 hectares of crops and 1,000 hectares of aquaculture damaged; hundreds of thousands of poultry and pigs died → food shortage, rising meat and vegetable prices | G24: 2

Sheet Pillar3_quarterly
A1: Year | B1: Quarter | C1: Food CPI Quarter YoY | D1: Diesel price Quarter YoY | E1: GRDP growth Quarter YoY | F1: number_of_extreme_days | G1: total_abnormal_events | H1: total_storm_events
A2: 2024 | B2: 4 | C2: 103.42 | D2: -11.019231 | E2: 7.01 | F2: 0 | G2: 4 | H2: 0
A3: 2024 | B3: 3 | C3: 103.30333 | D3: -6.2508674 | E3: 6.71 | F3: 0 | G3: 6 | H3: 2
A4: 2024 | B4: 2 | C4: 103.51333 | D4: 6.4056729 | E4: 6.8 | F4: 0 | G4: 6 | H4: 0
A5: 2024 | B5: 1 | C5: 103.09667 | D5: -2.3008258 | E5: 5.41 | F5: 3 | G5: 3 | H5: 0
A6: 2023 | B6: 4 | C6: 102.44 | D6: -9.8829793 | E6: 7 | F6: 2 | G6: 1 | H6: 0
A7: 2023 | B7: 3 | C7: 101.77 | D7: -16.998761 | E7: 6.22 | F7: 0 | G7: 2 | H7: 0
A8: 2023 | B8: 2 | C8: 103.74 | D8: -27.00546 | E8: 5.91 | F8: 0 | G8: 4 | H8: 0
A9: 2023 | B9: 1 | C9: 104.58667 | D9: -0.32951924 | E9: 5.81 | F9: 2 | G9: 1 | H9: 0
A10: 2022 | B10: 4 | C10: 105.64 | D10: 41.420381 | E10: 6.76 | F10: 2 | G10: 3 | H10: 0
A11: 2022 | B11: 3 | C11: 104.82333 | D11: 57.565267 | E11: 15.3 | F11: 0 | G11: 4 | H11: 0
A12: 2022 | B12: 2 | C12: 102.75333 | D12: 79.816476 | E12: 8.22 | F12: 0 | G12: 6 | H12: 0
A13: 2022 | B13: 1 | C13: 101.5 | D13: 60.897583 | E13: 5.91 | F13: 2 | G13: 4 | H13: 0
... A45: 2014 | B45: 1 | C45: 103.65667 | D45: 5.6913835 | E45: 6.5857131 | F45: 8 | G45: 0 | H45: 0

Sheet Pillar2_quarterly
A1: Year | B1: Quarter | C1: Paddy production (1000 tons) | D1: Rice production (tons) | E1: Fishery living w | F1: Fishery production (tons) | G1: Number of cows (1000) | H1: Number of pigs (1000) | I1: Number of poultry (1000) | J1: Meat production | K1: % of expenditure on non-staple food groups. | L1: Total markets/supermarkets | M1: PCI | N1: Number of policies on Food | O1: Rice self-sufficiency rate | P1: Meat self-sufficiency rate | Q1: Fish self-sufficiency rate | R1: Rice import rate | S1: Meat import rate | T1: Fish import rate | U1: Rice HHI for import partners | V1: Meat HHI for import partners | W1: Fish HHI for import partners | X1: Post-harvest lost rate
A2: 2024 | B2: 4 | C2: 862.8 | D2: =C2*90%*65%*1000 -> 504738 | E2: 132128 | F2: =E2*85%*40% -> 44923.52 | G2: 120.4 | H2: 1279.8 | I2: 37383 | J2: 439246 | K2: 0.89197843 | L2: 586 | M2: 68.38 | N2: 11 | O2: 0.53895371 | P2: 0.70563655 | Q2: 0.39198769 | R2: 0.016958486 | S2: 0.17542906 | T2: 0.12612281 | U2: 3049.0402 | V2: 2261.7819 | W2: 2977.9159 | X2: 12
A3: 2024 | B3: 3 | C3: 862.8 | D3: =C3*90%*65%*1000 -> 504738 | E3: 132128 | F3: =E3*85%*40% -> 44923.52 | G3: 120.4 | H3: 1279.8 | I3: 37383 | J3: 439246 | K3: 0.89197843 | L3: 586 | M3: 68.38 | N3: 11 | O3: 0.53895371 | P3: 0.70563655 | Q3: 0.39198769 | R3: 0.016958486 | S3: 0.17542906 | T3: 0.12612281 | U3: 3049.0402 | V3: 2261.7819 | W3: 2977.9159 | X3: 12
A4: 2024 | B4: 2 | C4: 862.8 | D4: =C4*90%*65%*1000 -> 504738 | E4: 132128 | F4: =E4*85%*40% -> 44923.52 | G4: 120.4 | H4: 1279.8 | I4: 37383 | J4: 439246 | K4: 0.89197843 | L4: 586 | M4: 68.38 | N4: 11 | O4: 0.53895371 | P4: 0.70563655 | Q4: 0.39198769 | R4: 0.016958486 | S4: 0.17542906 | T4: 0.12612281 | U4: 3049.0402 | V4: 2261.7819 | W4: 2977.9159 | X4: 12
A5: 2024 | B5: 1 | C5: 862.8 | D5: =C5*90%*65%*1000 -> 504738 | E5: 132128 | F5: =E5*85%*40% -> 44923.52 | G5: 120.4 | H5: 1279.8 | I5: 37383 | J5: 439246 | K5: 0.89197843 | L5: 586 | M5: 68.38 | N5: 11 | O5: 0.53895371 | P5: 0.70563655 | Q5: 0.39198769 | R5: 0.016958486 | S5: 0.17542906 | T5: 0.12612281 | U5: 3049.0402 | V5: 2261.7819 | W5: 2977.9159 | X5: 12
A6: 2023 | B6: 4 | C6: 939.3 | D6: =C6*90%*65%*1000 -> 549490.5 | E6: 127625 | F6: =E6*85%*40% -> 43392.5 | G6: 127.1 | H6: 1306.6 | I6: 36489 | J6: 425411 | K6: 0.88874951 | L6: 583 | M6: 67.15 | N6: 12 | O6: 0.58363504 | P6: 0.70855433 | Q6: 0.37970847 | R6: 0.014699902 | S6: 0.15514883 | T6: 0.12447767 | U6: 3193.89 | V6: 2487.1044 | W6: 3017.131 | X6: 12
A7: 2023 | B7: 3 | C7: 939.3 | D7: =C7*90%*65%*1000 -> 549490.5 | E7: 127625 | F7: =E7*85%*40% -> 43392.5 | G7: 127.1 | H7: 1306.6 | I7: 36489 | J7: 425411 | K7: 0.88874951 | L7: 583 | M7: 67.15 | N7: 12 | O7: 0.58363504 | P7: 0.70855433 | Q7: 0.37970847 | R7: 0.014699902 | S7: 0.15514883 | T7: 0.12447767 | U7: 3193.89 | V7: 2487.1044 | W7: 3017.131 | X7: 12
A8: 2023 | B8: 2 | C8: 939.3 | D8: =C8*90%*65%*1000 -> 549490.5 | E8: 127625 | F8: =E8*85%*40% -> 43392.5 | G8: 127.1 | H8: 1306.6 | I8: 36489 | J8: 425411 | K8: 0.88874951 | L8: 583 | M8: 67.15 | N8: 12 | O8: 0.58363504 | P8: 0.70855433 | Q8: 0.37970847 | R8: 0.014699902 | S8: 0.15514883 | T8: 0.12447767 | U8: 3193.89 | V8: 2487.1044 | W8: 3017.131 | X8: 12
A9: 2023 | B9: 1 | C9: 939.3 | D9: =C9*90%*65%*1000 -> 549490.5 | E9: 127625 | F9: =E9*85%*40% -> 43392.5 | G9: 127.1 | H9: 1306.6 | I9: 36489 | J9: 425411 | K9: 0.88874951 | L9: 583 | M9: 67.15 | N9: 12 | O9: 0.58363504 | P9: 0.70855433 | Q9: 0.37970847 | R9: 0.014699902 | S9: 0.15514883 | T9: 0.12447767 | U9: 3193.89 | V9: 2487.1044 | W9: 3017.131 | X9: 12
A10: 2022 | B10: 4 | C10: 952.5 | D10: =C10*90%*65%*1000 -> 557212.5 | E10: 123377 | F10: =E10*85%*40% -> 41948.18 | G10: 129.6 | H10: 1261.3 | I10: 35700 | J10: 248380.6 | K10: 0.85765646 | L10: 729 | M10: 66.74 | N10: 12 | O10: 0.63537716 | P10: 0.68570955 | Q10: 0.39315631 | R10: 0.014789436 | S10: 0.10628785 | T10: 0.1235204 | U10: 3361.4262 | V10: 2764.8051 | W10: 3075.6941 | X10: 12
A11: 2022 | B11: 3 | C11: 952.5 | D11: =C11*90%*65%*1000 -> 557212.5 | E11: 123377 | F11: =E11*85%*40% -> 41948.18 | G11: 129.6 | H11: 1261.3 | I11: 35700 | J11: 248380.6 | K11: 0.85765646 | L11: 729 | M11: 66.74 | N11: 12 | O11: 0.63537716 | P11: 0.68570955 | Q11: 0.39315631 | R11: 0.014789436 | S11: 0.10628785 | T11: 0.1235204 | U11: 3361.4262 | V11: 2764.8051 | W11: 3075.6941 | X11: 12
A12: 2022 | B12: 2 | C12: 952.5 | D12: =C12*90%*65%*1000 -> 557212.5 | E12: 123377 | F12: =E12*85%*40% -> 41948.18 | G12: 129.6 | H12: 1261.3 | I12: 35700 | J12: 248380.6 | K12: 0.85765646 | L12: 729 | M12: 66.74 | N12: 12 | O12: 0.63537716 | P12: 0.68570955 | Q12: 0.39315631 | R12: 0.014789436 | S12: 0.10628785 | T12: 0.1235204 | U12: 3361.4262 | V12: 2764.8051 | W12: 3075.6941 | X12: 12
A13: 2022 | B13: 1 | C13: 952.5 | D13: =C13*90%*65%*1000 -> 557212.5 | E13: 123377 | F13: =E13*85%*40% -> 41948.18 | G13: 129.6 | H13: 1261.3 | I13: 35700 | J13: 248380.6 | K13: 0.85765646 | L13: 729 | M13: 66.74 | N13: 12 | O13: 0.63537716 | P13: 0.68570955 | Q13: 0.39315631 | R13: 0.014789436 | S13: 0.10628785 | T13: 0.1235204 | U13: 3361.4262 | V13: 2764.8051 | W13: 3075.6941 | X13: 12
... A45: 2014 | B45: 1 | C45: 1175.5 | D45: =C45*90%*65%*1000 -> 687667.5 | E45: 86575 | F45: =E45*85%*40% -> 29435.5 | G45: 140.5 | H45: 1410.5 | I45: 22406 | J45: 188887.62 | K45: 0.85633029 | L45: 529 | M45: 58.89 | N45: 3 | O45: 0.72896339 | P45: 0.5587042 | Q45: 0.16478522 | R45: 0.00073421994 | S45: 0.026567112 | T45: 0.062663037 | U45: 4276.4032 | V45: 3826.582 | W45: 3732.7087 | X45: 12

Sheet Pillar1_quarterly
A1: Year | B1: Quarter | C1: GRDP per capital growth YoY | D1: Income per capital YoY | E1: Poverty rate YoY | F1: % semi-permanent housing and below | G1: % of Agriculture land | H1: Literacy rate of population aged 15+ | I1: Rate of trained labor (%) | J1: Social insurance coverage rate (%) | K1: Health insurance coverage rate (%) | L1: Expenditure on human health, population and family planning / GRDP (%) | M1: HHI for Employed population by economic sector
A2: 2024 | B2: 4 | C2: 108.79769 | D2: 109.9144 | E2: 0.1014575 | F2: 7.7 | G2: 46 | H2: 99.4 | I2: 53.9 | J2: 28.389539 | K2: 96.3 | L2: 1.5 | M2: 4533.98
A3: 2024 | B3: 3 | C3: 108.79769 | D3: 109.9144 | E3: 0.1014575 | F3: 7.7 | G3: 46 | H3: 99.4 | I3: 53.9 | J3: 28.389539 | K3: 96.3 | L3: 1.5 | M3: 4533.98
A4: 2024 | B4: 2 | C4: 108.79769 | D4: 109.9144 | E4: 0.1014575 | F4: 7.7 | G4: 46 | H4: 99.4 | I4: 53.9 | J4: 28.389539 | K4: 96.3 | L4: 1.5 | M4: 4533.98
A5: 2024 | B5: 1 | C5: 108.79769 | D5: 109.9144 | E5: 0.1014575 | F5: 7.7 | G5: 46 | H5: 99.4 | I5: 53.9 | J5: 28.389539 | K5: 96.3 | L5: 1.5 | M5: 4533.98
A6: 2023 | B6: 4 | C6: 106.49847 | D6: 106.9438 | E6: 0.1028912 | F6: 7.1 | G6: 46 | H6: 99.4 | I6: 50.8 | J6: 25.200592 | K6: 93 | L6: 1.7 | M6: 4481.36
A7: 2023 | B7: 3 | C7: 106.49847 | D7: 106.9438 | E7: 0.1028912 | F7: 7.1 | G7: 46 | H7: 99.4 | I7: 50.8 | J7: 25.200592 | K7: 93 | L7: 1.7 | M7: 4481.36
A8: 2023 | B8: 2 | C8: 106.49847 | D8: 106.9438 | E8: 0.1028912 | F8: 7.1 | G8: 46 | H8: 99.4 | I8: 50.8 | J8: 25.200592 | K8: 93 | L8: 1.7 | M8: 4481.36
A9: 2023 | B9: 1 | C9: 106.49847 | D9: 106.9438 | E9: 0.1028912 | F9: 7.1 | G9: 46 | H9: 99.4 | I9: 50.8 | J9: 25.200592 | K9: 93 | L9: 1.7 | M9: 4481.36
A10: 2022 | B10: 4 | C10: 109.96908 | D10: 107.01433 | E10: 0.142707 | F10: 7.1 | G10: 46.3 | H10: 99.4 | I10: 50.3 | J10: 24.396316 | K10: 91.7 | L10: 1.5 | M10: 4399.02
A11: 2022 | B11: 3 | C11: 109.96908 | D11: 107.01433 | E11: 0.142707 | F11: 7.1 | G11: 46.3 | H11: 99.4 | I11: 50.3 | J11: 24.396316 | K11: 91.7 | L11: 1.5 | M11: 4399.02
A12: 2022 | B12: 2 | C12: 109.96908 | D12: 107.01433 | E12: 0.142707 | F12: 7.1 | G12: 46.3 | H12: 99.4 | I12: 50.3 | J12: 24.396316 | K12: 91.7 | L12: 1.5 | M12: 4399.02
A13: 2022 | B13: 1 | C13: 109.96908 | D13: 107.01433 | E13: 0.142707 | F13: 7.1 | G13: 46.3 | H13: 99.4 | I13: 50.3 | J13: 24.396316 | K13: 91.7 | L13: 1.5 | M13: 4399.02
... A45: 2014 | B45: 1 | C45: 125.67064 | D45: 116.5486 | E45: 2.3 | F45: 7.3 | G45: 45.3 | H45: 98.6 | I45: 39.2 | J45: 17.212271 | K45: 68 | L45: 3.5 | M45: 3895.736

Sheet CRI index SOS
A1: P+A2 SOS | B1: Quarter | C1: Resilience Index | D1: Shocks | E1: Threshold3 | F1: Shocks 2 | G1: Threshold25 | H1: TIME | I1: CRI SOS | J1: Residual | K1: SOS L1 | L1: SOS L2
A2: 2024 | B2: 4 | C2: =POWER(Final_std_lv3[[#This Row],[Pillar 1: Resilience Capacities]]^10*Final_std_lv3[[#This Row],[Pillar 2: System Structure & Connectivity]]^7*Final_std_lv3[[#This Row],[Pillar 3: Exposure to Shocks & Stressors]]^6, 1/23) -> 1.7296928 | H2: 44 | I2: =_xlfn.FORECAST.LINEAR(Final_std_lv325[[#This Row],[TIME]],Final_std_lv325[Resilience Index],Final_std_lv325[TIME]) -> 1.7121294 | J2: =Final_std_lv325[[#This Row],[Resilience Index]]-Final_std_lv325[[#This Row],[CRI SOS]] -> 0.017563467 | K2: =Final_std_lv325[[#This Row],[CRI SOS]]-_xlfn.STDEV.S(J3:J10) -> 1.6821415 | L2: =Final_std_lv325[[#This Row],[CRI SOS]]-2*_xlfn.STDEV.S(J3:J10) -> 1.6521535
A3: 2024 | B3: 3 | C3: =POWER(Final_std_lv3[[#This Row],[Pillar 1: Resilience Capacities]]^10*Final_std_lv3[[#This Row],[Pillar 2: System Structure & Connectivity]]^7*Final_std_lv3[[#This Row],[Pillar 3: Exposure to Shocks & Stressors]]^6, 1/23) -> 1.6556934 | D3: Environmental/Biological | E3: 2 | H3: 43 | I3: =_xlfn.FORECAST.LINEAR(Final_std_lv325[[#This Row],[TIME]],Final_std_lv325[Resilience Index],Final_std_lv325[TIME]) -> 1.7066792 | J3: =Final_std_lv325[[#This Row],[Resilience Index]]-Final_std_lv325[[#This Row],[CRI SOS]] -> -0.050985846 | K3: =Final_std_lv325[[#This Row],[CRI SOS]]-_xlfn.STDEV.S(J4:J11) -> 1.6924519 | L3: =Final_std_lv325[[#This Row],[CRI SOS]]-2*_xlfn.STDEV.S(J4:J11) -> 1.6782245
A4: 2024 | B4: 2 | C4: =POWER(Final_std_lv3[[#This Row],[Pillar 1: Resilience Capacities]]^10*Final_std_lv3[[#This Row],[Pillar 2: System Structure & Connectivity]]^7*Final_std_lv3[[#This Row],[Pillar 3: Exposure to Shocks & Stressors]]^6, 1/23) -> 1.700893 | D4: Environmental/Biological | E4: 2 | H4: 42 | I4: =_xlfn.FORECAST.LINEAR(Final_std_lv325[[#This Row],[TIME]],Final_std_lv325[Resilience Index],Final_std_lv325[TIME]) -> 1.7012291 | J4: =Final_std_lv325[[#This Row],[Resilience Index]]-Final_std_lv325[[#This Row],[CRI SOS]] -> -0.00033616053 | K4: =Final_std_lv325[[#This Row],[CRI SOS]]-_xlfn.STDEV.S(J5:J12) -> 1.6844821 | L4: =Final_std_lv325[[#This Row],[CRI SOS]]-2*_xlfn.STDEV.S(J5:J12) -> 1.667735
A5: 2024 | B5: 1 | C5: =POWER(Final_std_lv3[[#This Row],[Pillar 1: Resilience Capacities]]^10*Final_std_lv3[[#This Row],[Pillar 2: System Structure & Connectivity]]^7*Final_std_lv3[[#This Row],[Pillar 3: Exposure to Shocks & Stressors]]^6, 1/23) -> 1.7177349 | H5: 41 | I5: =_xlfn.FORECAST.LINEAR(Final_std_lv325[[#This Row],[TIME]],Final_std_lv325[Resilience Index],Final_std_lv325[TIME]) -> 1.695779 | J5: =Final_std_lv325[[#This Row],[Resilience Index]]-Final_std_lv325[[#This Row],[CRI SOS]] -> 0.021955923 | K5: =Final_std_lv325[[#This Row],[CRI SOS]]-_xlfn.STDEV.S(J6:J13) -> 1.6781914 | L5: =Final_std_lv325[[#This Row],[CRI SOS]]-2*_xlfn.STDEV.S(J6:J13) -> 1.6606039
A6: 2023 | B6: 4 | C6: =POWER(Final_std_lv3[[#This Row],[Pillar 1: Resilience Capacities]]^10*Final_std_lv3[[#This Row],[Pillar 2: System Structure & Connectivity]]^7*Final_std_lv3[[#This Row],[Pillar 3: Exposure to Shocks & Stressors]]^6, 1/23) -> 1.721947 | H6: 40 | I6: =_xlfn.FORECAST.LINEAR(Final_std_lv325[[#This Row],[TIME]],Final_std_lv325[Resilience Index],Final_std_lv325[TIME]) -> 1.6903289 | J6: =Final_std_lv325[[#This Row],[Resilience Index]]-Final_std_lv325[[#This Row],[CRI SOS]] -> 0.031618097 | K6: =Final_std_lv325[[#This Row],[CRI SOS]]-_xlfn.STDEV.S(J7:J14) -> 1.6664079 | L6: =Final_std_lv325[[#This Row],[CRI SOS]]-2*_xlfn.STDEV.S(J7:J14) -> 1.642487
A7: 2023 | B7: 3 | C7: =POWER(Final_std_lv3[[#This Row],[Pillar 1: Resilience Capacities]]^10*Final_std_lv3[[#This Row],[Pillar 2: System Structure & Connectivity]]^7*Final_std_lv3[[#This Row],[Pillar 3: Exposure to Shocks & Stressors]]^6, 1/23) -> 1.7227419 | H7: 39 | I7: =_xlfn.FORECAST.LINEAR(Final_std_lv325[[#This Row],[TIME]],Final_std_lv325[Resilience Index],Final_std_lv325[TIME]) -> 1.6848787 | J7: =Final_std_lv325[[#This Row],[Resilience Index]]-Final_std_lv325[[#This Row],[CRI SOS]] -> 0.037863192 | K7: =Final_std_lv325[[#This Row],[CRI SOS]]-_xlfn.STDEV.S(J8:J15) -> 1.6448636 | L7: =Final_std_lv325[[#This Row],[CRI SOS]]-2*_xlfn.STDEV.S(J8:J15) -> 1.6048485
A8: 2023 | B8: 2 | C8: =POWER(Final_std_lv3[[#This Row],[Pillar 1: Resilience Capacities]]^10*Final_std_lv3[[#This Row],[Pillar 2: System Structure & Connectivity]]^7*Final_std_lv3[[#This Row],[Pillar 3: Exposure to Shocks & Stressors]]^6, 1/23) -> 1.7109991 | D8: Political/Policy | E8: 2 | H8: 38 | I8: =_xlfn.FORECAST.LINEAR(Final_std_lv325[[#This Row],[TIME]],Final_std_lv325[Resilience Index],Final_std_lv325[TIME]) -> 1.6794286 | J8: =Final_std_lv325[[#This Row],[Resilience Index]]-Final_std_lv325[[#This Row],[CRI SOS]] -> 0.031570449 | K8: =Final_std_lv325[[#This Row],[CRI SOS]]-_xlfn.STDEV.S(J9:J16) -> 1.6412565 | L8: =Final_std_lv325[[#This Row],[CRI SOS]]-2*_xlfn.STDEV.S(J9:J16) -> 1.6030844
A9: 2023 | B9: 1 | C9: =POWER(Final_std_lv3[[#This Row],[Pillar 1: Resilience Capacities]]^10*Final_std_lv3[[#This Row],[Pillar 2: System Structure & Connectivity]]^7*Final_std_lv3[[#This Row],[Pillar 3: Exposure to Shocks & Stressors]]^6, 1/23) -> 1.7113563 | H9: 37 | I9: =_xlfn.FORECAST.LINEAR(Final_std_lv325[[#This Row],[TIME]],Final_std_lv325[Resilience Index],Final_std_lv325[TIME]) -> 1.6739785 | J9: =Final_std_lv325[[#This Row],[Resilience Index]]-Final_std_lv325[[#This Row],[CRI SOS]] -> 0.037377808 | K9: =Final_std_lv325[[#This Row],[CRI SOS]]-_xlfn.STDEV.S(J10:J17) -> 1.6405292 | L9: =Final_std_lv325[[#This Row],[CRI SOS]]-2*_xlfn.STDEV.S(J10:J17) -> 1.6070799
A10: 2022 | B10: 4 | C10: =POWER(Final_std_lv3[[#This Row],[Pillar 1: Resilience Capacities]]^10*Final_std_lv3[[#This Row],[Pillar 2: System Structure & Connectivity]]^7*Final_std_lv3[[#This Row],[Pillar 3: Exposure to Shocks & Stressors]]^6, 1/23) -> 1.6742333 | H10: 36 | I10: =_xlfn.FORECAST.LINEAR(Final_std_lv325[[#This Row],[TIME]],Final_std_lv325[Resilience Index],Final_std_lv325[TIME]) -> 1.6685284 | J10: =Final_std_lv325[[#This Row],[Resilience Index]]-Final_std_lv325[[#This Row],[CRI SOS]] -> 0.0057049186 | K10: =Final_std_lv325[[#This Row],[CRI SOS]]-_xlfn.STDEV.S(J11:J18) -> 1.6360817 | L10: =Final_std_lv325[[#This Row],[CRI SOS]]-2*_xlfn.STDEV.S(J11:J18) -> 1.6036351
A11: 2022 | B11: 3 | C11: =POWER(Final_std_lv3[[#This Row],[Pillar 1: Resilience Capacities]]^10*Final_std_lv3[[#This Row],[Pillar 2: System Structure & Connectivity]]^7*Final_std_lv3[[#This Row],[Pillar 3: Exposure to Shocks & Stressors]]^6, 1/23) -> 1.6868369 | D11: Economic | E11: 2 | H11: 35 | I11: =_xlfn.FORECAST.LINEAR(Final_std_lv325[[#This Row],[TIME]],Final_std_lv325[Resilience Index],Final_std_lv325[TIME]) -> 1.6630782 | J11: =Final_std_lv325[[#This Row],[Resilience Index]]-Final_std_lv325[[#This Row],[CRI SOS]] -> 0.023758626 | K11: =Final_std_lv325[[#This Row],[CRI SOS]]-_xlfn.STDEV.S(J12:J19) -> 1.6345996 | L11: =Final_std_lv325[[#This Row],[CRI SOS]]-2*_xlfn.STDEV.S(J12:J19) -> 1.6061209
A12: 2022 | B12: 2 | C12: =POWER(Final_std_lv3[[#This Row],[Pillar 1: Resilience Capacities]]^10*Final_std_lv3[[#This Row],[Pillar 2: System Structure & Connectivity]]^7*Final_std_lv3[[#This Row],[Pillar 3: Exposure to Shocks & Stressors]]^6, 1/23) -> 1.6476242 | D12: Economic | E12: 2 | H12: 34 | I12: =_xlfn.FORECAST.LINEAR(Final_std_lv325[[#This Row],[TIME]],Final_std_lv325[Resilience Index],Final_std_lv325[TIME]) -> 1.6576281 | J12: =Final_std_lv325[[#This Row],[Resilience Index]]-Final_std_lv325[[#This Row],[CRI SOS]] -> -0.010003935 | K12: =Final_std_lv325[[#This Row],[CRI SOS]]-_xlfn.STDEV.S(J13:J20) -> 1.6278122 | L12: =Final_std_lv325[[#This Row],[CRI SOS]]-2*_xlfn.STDEV.S(J13:J20) -> 1.5979963
A13: 2022 | B13: 1 | C13: =POWER(Final_std_lv3[[#This Row],[Pillar 1: Resilience Capacities]]^10*Final_std_lv3[[#This Row],[Pillar 2: System Structure & Connectivity]]^7*Final_std_lv3[[#This Row],[Pillar 3: Exposure to Shocks & Stressors]]^6, 1/23) -> 1.6595274 | H13: 33 | I13: =_xlfn.FORECAST.LINEAR(Final_std_lv325[[#This Row],[TIME]],Final_std_lv325[Resilience Index],Final_std_lv325[TIME]) -> 1.652178 | J13: =Final_std_lv325[[#This Row],[Resilience Index]]-Final_std_lv325[[#This Row],[CRI SOS]] -> 0.0073494489 | K13: =Final_std_lv325[[#This Row],[CRI SOS]]-_xlfn.STDEV.S(J14:J21) -> 1.625613 | L13: =Final_std_lv325[[#This Row],[CRI SOS]]-2*_xlfn.STDEV.S(J14:J21) -> 1.5990481
A14: 2021 | B14: 4 | C14: =POWER(Final_std_lv3[[#This Row],[Pillar 1: Resilience Capacities]]^10*Final_std_lv3[[#This Row],[Pillar 2: System Structure & Connectivity]]^7*Final_std_lv3[[#This Row],[Pillar 3: Exposure to Shocks & Stressors]]^6, 1/23) -> 1.618276 | H14: 32 | I14: =_xlfn.FORECAST.LINEAR(Final_std_lv325[[#This Row],[TIME]],Final_std_lv325[Resilience Index],Final_std_lv325[TIME]) -> 1.6467278 | J14: =Final_std_lv325[[#This Row],[Resilience Index]]-Final_std_lv325[[#This Row],[CRI SOS]] -> -0.028451866 | K14: =Final_std_lv325[[#This Row],[CRI SOS]]-_xlfn.STDEV.S(J15:J22) -> 1.6098669 | L14: =Final_std_lv325[[#This Row],[CRI SOS]]-2*_xlfn.STDEV.S(J15:J22) -> 1.573006
A15: 2021 | B15: 3 | C15: =POWER(Final_std_lv3[[#This Row],[Pillar 1: Resilience Capacities]]^10*Final_std_lv3[[#This Row],[Pillar 2: System Structure & Connectivity]]^7*Final_std_lv3[[#This Row],[Pillar 3: Exposure to Shocks & Stressors]]^6, 1/23) -> 1.5558668 | D15: Economic | E15: 3 | H15: 31 | I15: =_xlfn.FORECAST.LINEAR(Final_std_lv325[[#This Row],[TIME]],Final_std_lv325[Resilience Index],Final_std_lv325[TIME]) -> 1.6412777 | J15: =Final_std_lv325[[#This Row],[Resilience Index]]-Final_std_lv325[[#This Row],[CRI SOS]] -> -0.08541091 | K15: =Final_std_lv325[[#This Row],[CRI SOS]]-_xlfn.STDEV.S(J16:J23) -> 1.6046505 | L15: =Final_std_lv325[[#This Row],[CRI SOS]]-2*_xlfn.STDEV.S(J16:J23) -> 1.5680232
A16: 2021 | B16: 2 | C16: =POWER(Final_std_lv3[[#This Row],[Pillar 1: Resilience Capacities]]^10*Final_std_lv3[[#This Row],[Pillar 2: System Structure & Connectivity]]^7*Final_std_lv3[[#This Row],[Pillar 3: Exposure to Shocks & Stressors]]^6, 1/23) -> 1.6102285 | D16: Economic | E16: 2 | H16: 30 | I16: =_xlfn.FORECAST.LINEAR(Final_std_lv325[[#This Row],[TIME]],Final_std_lv325[Resilience Index],Final_std_lv325[TIME]) -> 1.6358276 | J16: =Final_std_lv325[[#This Row],[Resilience Index]]-Final_std_lv325[[#This Row],[CRI SOS]] -> -0.025599058 | K16: =Final_std_lv325[[#This Row],[CRI SOS]]-_xlfn.STDEV.S(J17:J24) -> 1.5956736 | L16: =Final_std_lv325[[#This Row],[CRI SOS]]-2*_xlfn.STDEV.S(J17:J24) -> 1.5555196
A17: 2021 | B17: 1 | C17: =POWER(Final_std_lv3[[#This Row],[Pillar 1: Resilience Capacities]]^10*Final_std_lv3[[#This Row],[Pillar 2: System Structure & Connectivity]]^7*Final_std_lv3[[#This Row],[Pillar 3: Exposure to Shocks & Stressors]]^6, 1/23) -> 1.6266583 | D17: Economic | E17: 2 | H17: 29 | I17: =_xlfn.FORECAST.LINEAR(Final_std_lv325[[#This Row],[TIME]],Final_std_lv325[Resilience Index],Final_std_lv325[TIME]) -> 1.6303775 | J17: =Final_std_lv325[[#This Row],[Resilience Index]]-Final_std_lv325[[#This Row],[CRI SOS]] -> -0.0037192019 | K17: =Final_std_lv325[[#This Row],[CRI SOS]]-_xlfn.STDEV.S(J18:J25) -> 1.5901478 | L17: =Final_std_lv325[[#This Row],[CRI SOS]]-2*_xlfn.STDEV.S(J18:J25) -> 1.5499182
A18: 2020 | B18: 4 | C18: =POWER(Final_std_lv3[[#This Row],[Pillar 1: Resilience Capacities]]^10*Final_std_lv3[[#This Row],[Pillar 2: System Structure & Connectivity]]^7*Final_std_lv3[[#This Row],[Pillar 3: Exposure to Shocks & Stressors]]^6, 1/23) -> 1.6048239 | D18: Environmental/Biological | E18: 1 | H18: 28 | I18: =_xlfn.FORECAST.LINEAR(Final_std_lv325[[#This Row],[TIME]],Final_std_lv325[Resilience Index],Final_std_lv325[TIME]) -> 1.6249273 | J18: =Final_std_lv325[[#This Row],[Resilience Index]]-Final_std_lv325[[#This Row],[CRI SOS]] -> -0.020103481 | K18: =Final_std_lv325[[#This Row],[CRI SOS]]-_xlfn.STDEV.S(J19:J26) -> 1.5827285 | L18: =Final_std_lv325[[#This Row],[CRI SOS]]-2*_xlfn.STDEV.S(J19:J26) -> 1.5405297
A19: 2020 | B19: 3 | C19: =POWER(Final_std_lv3[[#This Row],[Pillar 1: Resilience Capacities]]^10*Final_std_lv3[[#This Row],[Pillar 2: System Structure & Connectivity]]^7*Final_std_lv3[[#This Row],[Pillar 3: Exposure to Shocks & Stressors]]^6, 1/23) -> 1.5779149 | D19: Political/Policy | E19: 1 | H19: 27 | I19: =_xlfn.FORECAST.LINEAR(Final_std_lv325[[#This Row],[TIME]],Final_std_lv325[Resilience Index],Final_std_lv325[TIME]) -> 1.6194772 | J19: =Final_std_lv325[[#This Row],[Resilience Index]]-Final_std_lv325[[#This Row],[CRI SOS]] -> -0.04156227 | K19: =Final_std_lv325[[#This Row],[CRI SOS]]-_xlfn.STDEV.S(J20:J27) -> 1.577268 | L19: =Final_std_lv325[[#This Row],[CRI SOS]]-2*_xlfn.STDEV.S(J20:J27) -> 1.5350588
A20: 2020 | B20: 2 | C20: =POWER(Final_std_lv3[[#This Row],[Pillar 1: Resilience Capacities]]^10*Final_std_lv3[[#This Row],[Pillar 2: System Structure & Connectivity]]^7*Final_std_lv3[[#This Row],[Pillar 3: Exposure to Shocks & Stressors]]^6, 1/23) -> 1.5549064 | D20: Political/Policy | E20: 2 | H20: 26 | I20: =_xlfn.FORECAST.LINEAR(Final_std_lv325[[#This Row],[TIME]],Final_std_lv325[Resilience Index],Final_std_lv325[TIME]) -> 1.6140271 | J20: =Final_std_lv325[[#This Row],[Resilience Index]]-Final_std_lv325[[#This Row],[CRI SOS]] -> -0.059120669 | K20: =Final_std_lv325[[#This Row],[CRI SOS]]-_xlfn.STDEV.S(J21:J28) -> 1.5753238 | L20: =Final_std_lv325[[#This Row],[CRI SOS]]-2*_xlfn.STDEV.S(J21:J28) -> 1.5366205
A21: 2020 | B21: 1 | C21: =POWER(Final_std_lv3[[#This Row],[Pillar 1: Resilience Capacities]]^10*Final_std_lv3[[#This Row],[Pillar 2: System Structure & Connectivity]]^7*Final_std_lv3[[#This Row],[Pillar 3: Exposure to Shocks & Stressors]]^6, 1/23) -> 1.547119 | H21: 25 | I21: =_xlfn.FORECAST.LINEAR(Final_std_lv325[[#This Row],[TIME]],Final_std_lv325[Resilience Index],Final_std_lv325[TIME]) -> 1.608577 | J21: =Final_std_lv325[[#This Row],[Resilience Index]]-Final_std_lv325[[#This Row],[CRI SOS]] -> -0.06145797 | K21: =Final_std_lv325[[#This Row],[CRI SOS]]-_xlfn.STDEV.S(J22:J29) -> 1.5768876 | L21: =Final_std_lv325[[#This Row],[CRI SOS]]-2*_xlfn.STDEV.S(J22:J29) -> 1.5451983
A22: 2019 | B22: 4 | C22: =POWER(Final_std_lv3[[#This Row],[Pillar 1: Resilience Capacities]]^10*Final_std_lv3[[#This Row],[Pillar 2: System Structure & Connectivity]]^7*Final_std_lv3[[#This Row],[Pillar 3: Exposure to Shocks & Stressors]]^6, 1/23) -> 1.6343193 | H22: 24 | I22: =_xlfn.FORECAST.LINEAR(Final_std_lv325[[#This Row],[TIME]],Final_std_lv325[Resilience Index],Final_std_lv325[TIME]) -> 1.6031268 | J22: =Final_std_lv325[[#This Row],[Resilience Index]]-Final_std_lv325[[#This Row],[CRI SOS]] -> 0.031192475 | K22: =Final_std_lv325[[#This Row],[CRI SOS]]-_xlfn.STDEV.S(J23:J30) -> 1.5738477 | L22: =Final_std_lv325[[#This Row],[CRI SOS]]-2*_xlfn.STDEV.S(J23:J30) -> 1.5445685
A23: 2019 | B23: 3 | C23: =POWER(Final_std_lv3[[#This Row],[Pillar 1: Resilience Capacities]]^10*Final_std_lv3[[#This Row],[Pillar 2: System Structure & Connectivity]]^7*Final_std_lv3[[#This Row],[Pillar 3: Exposure to Shocks & Stressors]]^6, 1/23) -> 1.6303903 | D23: Environmental/Biological | E23: 1 | F23: Environmental/Biological | G23: 1 | H23: 23 | I23: =_xlfn.FORECAST.LINEAR(Final_std_lv325[[#This Row],[TIME]],Final_std_lv325[Resilience Index],Final_std_lv325[TIME]) -> 1.5976767 | J23: =Final_std_lv325[[#This Row],[Resilience Index]]-Final_std_lv325[[#This Row],[CRI SOS]] -> 0.032713629 | K23: =Final_std_lv325[[#This Row],[CRI SOS]]-_xlfn.STDEV.S(J24:J31) -> 1.5710893 | L23: =Final_std_lv325[[#This Row],[CRI SOS]]-2*_xlfn.STDEV.S(J24:J31) -> 1.544502
A24: 2019 | B24: 2 | C24: =POWER(Final_std_lv3[[#This Row],[Pillar 1: Resilience Capacities]]^10*Final_std_lv3[[#This Row],[Pillar 2: System Structure & Connectivity]]^7*Final_std_lv3[[#This Row],[Pillar 3: Exposure to Shocks & Stressors]]^6, 1/23) -> 1.6220435 | D24: Environmental/Biological | E24: 2 | H24: 22 | I24: =_xlfn.FORECAST.LINEAR(Final_std_lv325[[#This Row],[TIME]],Final_std_lv325[Resilience Index],Final_std_lv325[TIME]) -> 1.5922266 | J24: =Final_std_lv325[[#This Row],[Resilience Index]]-Final_std_lv325[[#This Row],[CRI SOS]] -> 0.02981687 | K24: =Final_std_lv325[[#This Row],[CRI SOS]]-_xlfn.STDEV.S(J25:J32) -> 1.5669464 | L24: =Final_std_lv325[[#This Row],[CRI SOS]]-2*_xlfn.STDEV.S(J25:J32) -> 1.5416663
A25: 2019 | B25: 1 | C25: =POWER(Final_std_lv3[[#This Row],[Pillar 1: Resilience Capacities]]^10*Final_std_lv3[[#This Row],[Pillar 2: System Structure & Connectivity]]^7*Final_std_lv3[[#This Row],[Pillar 3: Exposure to Shocks & Stressors]]^6, 1/23) -> 1.5854586 | H25: 21 | I25: =_xlfn.FORECAST.LINEAR(Final_std_lv325[[#This Row],[TIME]],Final_std_lv325[Resilience Index],Final_std_lv325[TIME]) -> 1.5867765 | J25: =Final_std_lv325[[#This Row],[Resilience Index]]-Final_std_lv325[[#This Row],[CRI SOS]] -> -0.0013178171 | K25: =Final_std_lv325[[#This Row],[CRI SOS]]-_xlfn.STDEV.S(J26:J33) -> 1.5571977 | L25: =Final_std_lv325[[#This Row],[CRI SOS]]-2*_xlfn.STDEV.S(J26:J33) -> 1.5276189
A26: 2018 | B26: 4 | C26: =POWER(Final_std_lv3[[#This Row],[Pillar 1: Resilience Capacities]]^10*Final_std_lv3[[#This Row],[Pillar 2: System Structure & Connectivity]]^7*Final_std_lv3[[#This Row],[Pillar 3: Exposure to Shocks & Stressors]]^6, 1/23) -> 1.5339288 | H26: 20 | I26: =_xlfn.FORECAST.LINEAR(Final_std_lv325[[#This Row],[TIME]],Final_std_lv325[Resilience Index],Final_std_lv325[TIME]) -> 1.5813263 | J26: =Final_std_lv325[[#This Row],[Resilience Index]]-Final_std_lv325[[#This Row],[CRI SOS]] -> -0.047397535 | K26: =Final_std_lv325[[#This Row],[CRI SOS]]-_xlfn.STDEV.S(J27:J34) -> 1.5446503 | L26: =Final_std_lv325[[#This Row],[CRI SOS]]-2*_xlfn.STDEV.S(J27:J34) -> 1.5079744
A27: 2018 | B27: 3 | C27: =POWER(Final_std_lv3[[#This Row],[Pillar 1: Resilience Capacities]]^10*Final_std_lv3[[#This Row],[Pillar 2: System Structure & Connectivity]]^7*Final_std_lv3[[#This Row],[Pillar 3: Exposure to Shocks & Stressors]]^6, 1/23) -> 1.5342002 | D27: Economic | E27: 2 | H27: 19 | I27: =_xlfn.FORECAST.LINEAR(Final_std_lv325[[#This Row],[TIME]],Final_std_lv325[Resilience Index],Final_std_lv325[TIME]) -> 1.5758762 | J27: =Final_std_lv325[[#This Row],[Resilience Index]]-Final_std_lv325[[#This Row],[CRI SOS]] -> -0.041676033 | K27: =Final_std_lv325[[#This Row],[CRI SOS]]-_xlfn.STDEV.S(J28:J35) -> 1.5464406 | L27: =Final_std_lv325[[#This Row],[CRI SOS]]-2*_xlfn.STDEV.S(J28:J35) -> 1.5170051
A28: 2018 | B28: 2 | C28: =POWER(Final_std_lv3[[#This Row],[Pillar 1: Resilience Capacities]]^10*Final_std_lv3[[#This Row],[Pillar 2: System Structure & Connectivity]]^7*Final_std_lv3[[#This Row],[Pillar 3: Exposure to Shocks & Stressors]]^6, 1/23) -> 1.5798131 | H28: 18 | I28: =_xlfn.FORECAST.LINEAR(Final_std_lv325[[#This Row],[TIME]],Final_std_lv325[Resilience Index],Final_std_lv325[TIME]) -> 1.5704261 | J28: =Final_std_lv325[[#This Row],[Resilience Index]]-Final_std_lv325[[#This Row],[CRI SOS]] -> 0.0093870276 | K28: =Final_std_lv325[[#This Row],[CRI SOS]]-_xlfn.STDEV.S(J29:J36) -> 1.5319452 | L28: =Final_std_lv325[[#This Row],[CRI SOS]]-2*_xlfn.STDEV.S(J29:J36) -> 1.4934643
A29: 2018 | B29: 1 | C29: =POWER(Final_std_lv3[[#This Row],[Pillar 1: Resilience Capacities]]^10*Final_std_lv3[[#This Row],[Pillar 2: System Structure & Connectivity]]^7*Final_std_lv3[[#This Row],[Pillar 3: Exposure to Shocks & Stressors]]^6, 1/23) -> 1.5594536 | D29: Political/Policy | E29: 2 | H29: 17 | I29: =_xlfn.FORECAST.LINEAR(Final_std_lv325[[#This Row],[TIME]],Final_std_lv325[Resilience Index],Final_std_lv325[TIME]) -> 1.5649759 | J29: =Final_std_lv325[[#This Row],[Resilience Index]]-Final_std_lv325[[#This Row],[CRI SOS]] -> -0.0055223709 | K29: =Final_std_lv325[[#This Row],[CRI SOS]]-_xlfn.STDEV.S(J30:J37) -> 1.5270062 | L29: =Final_std_lv325[[#This Row],[CRI SOS]]-2*_xlfn.STDEV.S(J30:J37) -> 1.4890364
A30: 2017 | B30: 4 | C30: =POWER(Final_std_lv3[[#This Row],[Pillar 1: Resilience Capacities]]^10*Final_std_lv3[[#This Row],[Pillar 2: System Structure & Connectivity]]^7*Final_std_lv3[[#This Row],[Pillar 3: Exposure to Shocks & Stressors]]^6, 1/23) -> 1.5608961 | H30: 16 | I30: =_xlfn.FORECAST.LINEAR(Final_std_lv325[[#This Row],[TIME]],Final_std_lv325[Resilience Index],Final_std_lv325[TIME]) -> 1.5595258 | J30: =Final_std_lv325[[#This Row],[Resilience Index]]-Final_std_lv325[[#This Row],[CRI SOS]] -> 0.0013702401 | K30: =Final_std_lv325[[#This Row],[CRI SOS]]-_xlfn.STDEV.S(J31:J38) -> 1.5181255 | L30: =Final_std_lv325[[#This Row],[CRI SOS]]-2*_xlfn.STDEV.S(J31:J38) -> 1.4767252
A31: 2017 | B31: 3 | C31: =POWER(Final_std_lv3[[#This Row],[Pillar 1: Resilience Capacities]]^10*Final_std_lv3[[#This Row],[Pillar 2: System Structure & Connectivity]]^7*Final_std_lv3[[#This Row],[Pillar 3: Exposure to Shocks & Stressors]]^6, 1/23) -> 1.5673097 | H31: 15 | I31: =_xlfn.FORECAST.LINEAR(Final_std_lv325[[#This Row],[TIME]],Final_std_lv325[Resilience Index],Final_std_lv325[TIME]) -> 1.5540757 | J31: =Final_std_lv325[[#This Row],[Resilience Index]]-Final_std_lv325[[#This Row],[CRI SOS]] -> 0.013233965 | K31: =Final_std_lv325[[#This Row],[CRI SOS]]-_xlfn.STDEV.S(J32:J39) -> 1.5087436 | L31: =Final_std_lv325[[#This Row],[CRI SOS]]-2*_xlfn.STDEV.S(J32:J39) -> 1.4634115
A32: 2017 | B32: 2 | C32: =POWER(Final_std_lv3[[#This Row],[Pillar 1: Resilience Capacities]]^10*Final_std_lv3[[#This Row],[Pillar 2: System Structure & Connectivity]]^7*Final_std_lv3[[#This Row],[Pillar 3: Exposure to Shocks & Stressors]]^6, 1/23) -> 1.5709838 | H32: 14 | I32: =_xlfn.FORECAST.LINEAR(Final_std_lv325[[#This Row],[TIME]],Final_std_lv325[Resilience Index],Final_std_lv325[TIME]) -> 1.5486256 | J32: =Final_std_lv325[[#This Row],[Resilience Index]]-Final_std_lv325[[#This Row],[CRI SOS]] -> 0.022358264 | K32: =Final_std_lv325[[#This Row],[CRI SOS]]-_xlfn.STDEV.S(J33:J40) -> 1.4983111 | L32: =Final_std_lv325[[#This Row],[CRI SOS]]-2*_xlfn.STDEV.S(J33:J40) -> 1.4479966
A33: 2017 | B33: 1 | C33: =POWER(Final_std_lv3[[#This Row],[Pillar 1: Resilience Capacities]]^10*Final_std_lv3[[#This Row],[Pillar 2: System Structure & Connectivity]]^7*Final_std_lv3[[#This Row],[Pillar 3: Exposure to Shocks & Stressors]]^6, 1/23) -> 1.5800737 | H33: 13 | I33: =_xlfn.FORECAST.LINEAR(Final_std_lv325[[#This Row],[TIME]],Final_std_lv325[Resilience Index],Final_std_lv325[TIME]) -> 1.5431754 | J33: =Final_std_lv325[[#This Row],[Resilience Index]]-Final_std_lv325[[#This Row],[CRI SOS]] -> 0.03689824 | K33: =Final_std_lv325[[#This Row],[CRI SOS]]-_xlfn.STDEV.S(J34:J41) -> 1.4904642 | L33: =Final_std_lv325[[#This Row],[CRI SOS]]-2*_xlfn.STDEV.S(J34:J41) -> 1.4377529
A34: 2016 | B34: 4 | C34: =POWER(Final_std_lv3[[#This Row],[Pillar 1: Resilience Capacities]]^10*Final_std_lv3[[#This Row],[Pillar 2: System Structure & Connectivity]]^7*Final_std_lv3[[#This Row],[Pillar 3: Exposure to Shocks & Stressors]]^6, 1/23) -> 1.6236405 | D34: Environmental/Biological | E34: 1 | H34: 12 | I34: =_xlfn.FORECAST.LINEAR(Final_std_lv325[[#This Row],[TIME]],Final_std_lv325[Resilience Index],Final_std_lv325[TIME]) -> 1.5377253 | J34: =Final_std_lv325[[#This Row],[Resilience Index]]-Final_std_lv325[[#This Row],[CRI SOS]] -> 0.085915197 | K34: =Final_std_lv325[[#This Row],[CRI SOS]]-_xlfn.STDEV.S(J35:J42) -> 1.4900792 | L34: =Final_std_lv325[[#This Row],[CRI SOS]]-2*_xlfn.STDEV.S(J35:J42) -> 1.4424331
A35: 2016 | B35: 3 | C35: =POWER(Final_std_lv3[[#This Row],[Pillar 1: Resilience Capacities]]^10*Final_std_lv3[[#This Row],[Pillar 2: System Structure & Connectivity]]^7*Final_std_lv3[[#This Row],[Pillar 3: Exposure to Shocks & Stressors]]^6, 1/23) -> 1.5355893 | H35: 11 | I35: =_xlfn.FORECAST.LINEAR(Final_std_lv325[[#This Row],[TIME]],Final_std_lv325[Resilience Index],Final_std_lv325[TIME]) -> 1.5322752 | J35: =Final_std_lv325[[#This Row],[Resilience Index]]-Final_std_lv325[[#This Row],[CRI SOS]] -> 0.0033141257 | K35: =Final_std_lv325[[#This Row],[CRI SOS]]-_xlfn.STDEV.S(J36:J43) -> 1.4840228 | L35: =Final_std_lv325[[#This Row],[CRI SOS]]-2*_xlfn.STDEV.S(J36:J43) -> 1.4357704
A36: 2016 | B36: 2 | C36: =POWER(Final_std_lv3[[#This Row],[Pillar 1: Resilience Capacities]]^10*Final_std_lv3[[#This Row],[Pillar 2: System Structure & Connectivity]]^7*Final_std_lv3[[#This Row],[Pillar 3: Exposure to Shocks & Stressors]]^6, 1/23) -> 1.6206565 | D36: Environmental/Biological | E36: 2 | H36: 10 | I36: =_xlfn.FORECAST.LINEAR(Final_std_lv325[[#This Row],[TIME]],Final_std_lv325[Resilience Index],Final_std_lv325[TIME]) -> 1.5268251 | J36: =Final_std_lv325[[#This Row],[Resilience Index]]-Final_std_lv325[[#This Row],[CRI SOS]] -> 0.09383148 | K36: =Final_std_lv325[[#This Row],[CRI SOS]]-_xlfn.STDEV.S(J37:J44) -> 1.4937189 | L36: =Final_std_lv325[[#This Row],[CRI SOS]]-2*_xlfn.STDEV.S(J37:J44) -> 1.4606128
A37: 2016 | B37: 1 | C37: =POWER(Final_std_lv3[[#This Row],[Pillar 1: Resilience Capacities]]^10*Final_std_lv3[[#This Row],[Pillar 2: System Structure & Connectivity]]^7*Final_std_lv3[[#This Row],[Pillar 3: Exposure to Shocks & Stressors]]^6, 1/23) -> 1.5964236 | D37: Environmental/Biological | E37: 2 | H37: 9 | I37: =_xlfn.FORECAST.LINEAR(Final_std_lv325[[#This Row],[TIME]],Final_std_lv325[Resilience Index],Final_std_lv325[TIME]) -> 1.5213749 | J37: =Final_std_lv325[[#This Row],[Resilience Index]]-Final_std_lv325[[#This Row],[CRI SOS]] -> 0.07504864 | K37: =Final_std_lv325[[#This Row],[CRI SOS]]-_xlfn.STDEV.S(J38:J45) -> 1.5094545 | L37: =Final_std_lv325[[#This Row],[CRI SOS]]-2*_xlfn.STDEV.S(J38:J45) -> 1.4975341
A38: 2015 | B38: 4 | C38: =POWER(Final_std_lv3[[#This Row],[Pillar 1: Resilience Capacities]]^10*Final_std_lv3[[#This Row],[Pillar 2: System Structure & Connectivity]]^7*Final_std_lv3[[#This Row],[Pillar 3: Exposure to Shocks & Stressors]]^6, 1/23) -> 1.4977222 | D38: Environmental/Biological | E38: 2 | H38: 8 | I38: =_xlfn.FORECAST.LINEAR(Final_std_lv325[[#This Row],[TIME]],Final_std_lv325[Resilience Index],Final_std_lv325[TIME]) -> 1.5159248 | J38: =Final_std_lv325[[#This Row],[Resilience Index]]-Final_std_lv325[[#This Row],[CRI SOS]] -> -0.018202629 | K38: =Final_std_lv325[[#This Row],[CRI SOS]]-_xlfn.STDEV.S(J39:J46) -> 1.5031031 | L38: =Final_std_lv325[[#This Row],[CRI SOS]]-2*_xlfn.STDEV.S(J39:J46) -> 1.4902814
A39: 2015 | B39: 3 | C39: =POWER(Final_std_lv3[[#This Row],[Pillar 1: Resilience Capacities]]^10*Final_std_lv3[[#This Row],[Pillar 2: System Structure & Connectivity]]^7*Final_std_lv3[[#This Row],[Pillar 3: Exposure to Shocks & Stressors]]^6, 1/23) -> 1.4932242 | H39: 7 | I39: =_xlfn.FORECAST.LINEAR(Final_std_lv325[[#This Row],[TIME]],Final_std_lv325[Resilience Index],Final_std_lv325[TIME]) -> 1.5104747 | J39: =Final_std_lv325[[#This Row],[Resilience Index]]-Final_std_lv325[[#This Row],[CRI SOS]] -> -0.017250532 | K39: =Final_std_lv325[[#This Row],[CRI SOS]]-_xlfn.STDEV.S(J40:J47) -> 1.4965649 | L39: =Final_std_lv325[[#This Row],[CRI SOS]]-2*_xlfn.STDEV.S(J40:J47) -> 1.4826551
A40: 2015 | B40: 2 | C40: =POWER(Final_std_lv3[[#This Row],[Pillar 1: Resilience Capacities]]^10*Final_std_lv3[[#This Row],[Pillar 2: System Structure & Connectivity]]^7*Final_std_lv3[[#This Row],[Pillar 3: Exposure to Shocks & Stressors]]^6, 1/23) -> 1.4786286 | D40: Political/Policy | E40: 2 | H40: 6 | I40: =_xlfn.FORECAST.LINEAR(Final_std_lv325[[#This Row],[TIME]],Final_std_lv325[Resilience Index],Final_std_lv325[TIME]) -> 1.5050246 | J40: =Final_std_lv325[[#This Row],[Resilience Index]]-Final_std_lv325[[#This Row],[CRI SOS]] -> -0.026395956 | K40: =Final_std_lv325[[#This Row],[CRI SOS]]-_xlfn.STDEV.S(J41:J48) -> 1.4896644 | L40: =Final_std_lv325[[#This Row],[CRI SOS]]-2*_xlfn.STDEV.S(J41:J48) -> 1.4743043
...

Sheet Pillar1 SOS
A1: Year | B1: Quarter | C1: Pillar1 Index | D1: Shocks | E1: Threshold3 | F1: Shocks 2 | G1: Threshold25 | H1: TIME | I1: Pillar1 SOS | J1: Residual | K1: SOS T1 | L1: SOS T2 | M1: TIME2 | N1: Pillar1 SOS2 | O1: Residuals2 | P1: SOS T1_2 | Q1: SOS T2_2
A2: 2024 | B2: 4 | C2: =POWER(Pillar1_quarterly1018[[#This Row],[A. ASSET]]^10*Pillar1_quarterly1018[[#This Row],[B. ADAPTIVE CAPACITY]],1/10) -> 1.786421 | H2: 44 | I2: =_xlfn.FORECAST.LINEAR(Table28[[#This Row],[TIME]],Table28[Pillar1 Index],Table28[TIME]) -> 1.743569 | J2: ='Pillar1 SOS'!$C2-'Pillar1 SOS'!$I2 -> 0.042851996 | K2: ='Pillar1 SOS'!$I2-_xlfn.STDEV.S('Pillar1 SOS'!$J$2:$J$45) -> 1.660789 | L2: ='Pillar1 SOS'!$I2-2*_xlfn.STDEV.S('Pillar1 SOS'!$J$2:$J$45) -> 1.5780091 | M2: 11 | N2: =_xlfn.FORECAST.LINEAR(Table28[[#This Row],[TIME2]],Table28[Pillar1 Index],Table28[TIME2]) -> 1.7334914 | O2: =Table28[[#This Row],[Pillar1 Index]]-Table28[[#This Row],[Pillar1 SOS2]] -> 0.052929565 | P2: =N2-_xlfn.STDEV.S(Table28[Residuals2]) -> 1.6511506 | Q2: =N2-2*_xlfn.STDEV.S(Table28[Residuals2]) -> 1.5688097
A3: 2024 | B3: 3 | C3: =POWER(Pillar1_quarterly1018[[#This Row],[A. ASSET]]^10*Pillar1_quarterly1018[[#This Row],[B. ADAPTIVE CAPACITY]],1/10) -> 1.786421 | D3: Environmental/Biological | E3: 2 | H3: 43 | I3: =_xlfn.FORECAST.LINEAR(Table28[[#This Row],[TIME]],Table28[Pillar1 Index],Table28[TIME]) -> 1.7360694 | J3: ='Pillar1 SOS'!$C3-'Pillar1 SOS'!$I3 -> 0.050351582 | K3: ='Pillar1 SOS'!$I3-_xlfn.STDEV.S('Pillar1 SOS'!$J$2:$J$45) -> 1.6532895 | L3: ='Pillar1 SOS'!$I3-2*_xlfn.STDEV.S('Pillar1 SOS'!$J$2:$J$45) -> 1.5705095 | M3: 11 | N3: =_xlfn.FORECAST.LINEAR(Table28[[#This Row],[TIME2]],Table28[Pillar1 Index],Table28[TIME2]) -> 1.7334914 | O3: =Table28[[#This Row],[Pillar1 Index]]-Table28[[#This Row],[Pillar1 SOS2]] -> 0.052929565 | P3: =N3-_xlfn.STDEV.S(Table28[Residuals2]) -> 1.6511506 | Q3: =N3-2*_xlfn.STDEV.S(Table28[Residuals2]) -> 1.5688097
A4: 2024 | B4: 2 | C4: =POWER(Pillar1_quarterly1018[[#This Row],[A. ASSET]]^10*Pillar1_quarterly1018[[#This Row],[B. ADAPTIVE CAPACITY]],1/10) -> 1.786421 | D4: Environmental/Biological | E4: 2 | H4: 42 | I4: =_xlfn.FORECAST.LINEAR(Table28[[#This Row],[TIME]],Table28[Pillar1 Index],Table28[TIME]) -> 1.7285698 | J4: ='Pillar1 SOS'!$C4-'Pillar1 SOS'!$I4 -> 0.057851168 | K4: ='Pillar1 SOS'!$I4-_xlfn.STDEV.S('Pillar1 SOS'!$J$2:$J$45) -> 1.6457899 | L4: ='Pillar1 SOS'!$I4-2*_xlfn.STDEV.S('Pillar1 SOS'!$J$2:$J$45) -> 1.5630099 | M4: 11 | N4: =_xlfn.FORECAST.LINEAR(Table28[[#This Row],[TIME2]],Table28[Pillar1 Index],Table28[TIME2]) -> 1.7334914 | O4: =Table28[[#This Row],[Pillar1 Index]]-Table28[[#This Row],[Pillar1 SOS2]] -> 0.052929565 | P4: =N4-_xlfn.STDEV.S(Table28[Residuals2]) -> 1.6511506 | Q4: =N4-2*_xlfn.STDEV.S(Table28[Residuals2]) -> 1.5688097
A5: 2024 | B5: 1 | C5: =POWER(Pillar1_quarterly1018[[#This Row],[A. ASSET]]^10*Pillar1_quarterly1018[[#This Row],[B. ADAPTIVE CAPACITY]],1/10) -> 1.786421 | H5: 41 | I5: =_xlfn.FORECAST.LINEAR(Table28[[#This Row],[TIME]],Table28[Pillar1 Index],Table28[TIME]) -> 1.7210702 | J5: ='Pillar1 SOS'!$C5-'Pillar1 SOS'!$I5 -> 0.065350754 | K5: ='Pillar1 SOS'!$I5-_xlfn.STDEV.S('Pillar1 SOS'!$J$2:$J$45) -> 1.6382903 | L5: ='Pillar1 SOS'!$I5-2*_xlfn.STDEV.S('Pillar1 SOS'!$J$2:$J$45) -> 1.5555104 | M5: 11 | N5: =_xlfn.FORECAST.LINEAR(Table28[[#This Row],[TIME2]],Table28[Pillar1 Index],Table28[TIME2]) -> 1.7334914 | O5: =Table28[[#This Row],[Pillar1 Index]]-Table28[[#This Row],[Pillar1 SOS2]] -> 0.052929565 | P5: =N5-_xlfn.STDEV.S(Table28[Residuals2]) -> 1.6511506 | Q5: =N5-2*_xlfn.STDEV.S(Table28[Residuals2]) -> 1.5688097
A6: 2023 | B6: 4 | C6: =POWER(Pillar1_quarterly1018[[#This Row],[A. ASSET]]^10*Pillar1_quarterly1018[[#This Row],[B. ADAPTIVE CAPACITY]],1/10) -> 1.7412789 | H6: 40 | I6: =_xlfn.FORECAST.LINEAR(Table28[[#This Row],[TIME]],Table28[Pillar1 Index],Table28[TIME]) -> 1.7135706 | J6: ='Pillar1 SOS'!$C6-'Pillar1 SOS'!$I6 -> 0.027708228 | K6: ='Pillar1 SOS'!$I6-_xlfn.STDEV.S('Pillar1 SOS'!$J$2:$J$45) -> 1.6307907 | L6: ='Pillar1 SOS'!$I6-2*_xlfn.STDEV.S('Pillar1 SOS'!$J$2:$J$45) -> 1.5480108 | M6: 10 | N6: =_xlfn.FORECAST.LINEAR(Table28[[#This Row],[TIME2]],Table28[Pillar1 Index],Table28[TIME2]) -> 1.7032587 | O6: =Table28[[#This Row],[Pillar1 Index]]-Table28[[#This Row],[Pillar1 SOS2]] -> 0.038020158 | P6: =N6-_xlfn.STDEV.S(Table28[Residuals2]) -> 1.6209179 | Q6: =N6-2*_xlfn.STDEV.S(Table28[Residuals2]) -> 1.538577
A7: 2023 | B7: 3 | C7: =POWER(Pillar1_quarterly1018[[#This Row],[A. ASSET]]^10*Pillar1_quarterly1018[[#This Row],[B. ADAPTIVE CAPACITY]],1/10) -> 1.7412789 | H7: 39 | I7: =_xlfn.FORECAST.LINEAR(Table28[[#This Row],[TIME]],Table28[Pillar1 Index],Table28[TIME]) -> 1.706071 | J7: ='Pillar1 SOS'!$C7-'Pillar1 SOS'!$I7 -> 0.035207814 | K7: ='Pillar1 SOS'!$I7-_xlfn.STDEV.S('Pillar1 SOS'!$J$2:$J$45) -> 1.6232911 | L7: ='Pillar1 SOS'!$I7-2*_xlfn.STDEV.S('Pillar1 SOS'!$J$2:$J$45) -> 1.5405112 | M7: 10 | N7: =_xlfn.FORECAST.LINEAR(Table28[[#This Row],[TIME2]],Table28[Pillar1 Index],Table28[TIME2]) -> 1.7032587 | O7: =Table28[[#This Row],[Pillar1 Index]]-Table28[[#This Row],[Pillar1 SOS2]] -> 0.038020158 | P7: =N7-_xlfn.STDEV.S(Table28[Residuals2]) -> 1.6209179 | Q7: =N7-2*_xlfn.STDEV.S(Table28[Residuals2]) -> 1.538577
A8: 2023 | B8: 2 | C8: =POWER(Pillar1_quarterly1018[[#This Row],[A. ASSET]]^10*Pillar1_quarterly1018[[#This Row],[B. ADAPTIVE CAPACITY]],1/10) -> 1.7412789 | D8: Political/Policy | E8: 2 | H8: 38 | I8: =_xlfn.FORECAST.LINEAR(Table28[[#This Row],[TIME]],Table28[Pillar1 Index],Table28[TIME]) -> 1.6985715 | J8: ='Pillar1 SOS'!$C8-'Pillar1 SOS'!$I8 -> 0.0427074 | K8: ='Pillar1 SOS'!$I8-_xlfn.STDEV.S('Pillar1 SOS'!$J$2:$J$45) -> 1.6157915 | L8: ='Pillar1 SOS'!$I8-2*_xlfn.STDEV.S('Pillar1 SOS'!$J$2:$J$45) -> 1.5330116 | M8: 10 | N8: =_xlfn.FORECAST.LINEAR(Table28[[#This Row],[TIME2]],Table28[Pillar1 Index],Table28[TIME2]) -> 1.7032587 | O8: =Table28[[#This Row],[Pillar1 Index]]-Table28[[#This Row],[Pillar1 SOS2]] -> 0.038020158 | P8: =N8-_xlfn.STDEV.S(Table28[Residuals2]) -> 1.6209179 | Q8: =N8-2*_xlfn.STDEV.S(Table28[Residuals2]) -> 1.538577
A9: 2023 | B9: 1 | C9: =POWER(Pillar1_quarterly1018[[#This Row],[A. ASSET]]^10*Pillar1_quarterly1018[[#This Row],[B. ADAPTIVE CAPACITY]],1/10) -> 1.7412789 | H9: 37 | I9: =_xlfn.FORECAST.LINEAR(Table28[[#This Row],[TIME]],Table28[Pillar1 Index],Table28[TIME]) -> 1.6910719 | J9: ='Pillar1 SOS'!$C9-'Pillar1 SOS'!$I9 -> 0.050206985 | K9: ='Pillar1 SOS'!$I9-_xlfn.STDEV.S('Pillar1 SOS'!$J$2:$J$45) -> 1.6082919 | L9: ='Pillar1 SOS'!$I9-2*_xlfn.STDEV.S('Pillar1 SOS'!$J$2:$J$45) -> 1.525512 | M9: 10 | N9: =_xlfn.FORECAST.LINEAR(Table28[[#This Row],[TIME2]],Table28[Pillar1 Index],Table28[TIME2]) -> 1.7032587 | O9: =Table28[[#This Row],[Pillar1 Index]]-Table28[[#This Row],[Pillar1 SOS2]] -> 0.038020158 | P9: =N9-_xlfn.STDEV.S(Table28[Residuals2]) -> 1.6209179 | Q9: =N9-2*_xlfn.STDEV.S(Table28[Residuals2]) -> 1.538577
A10: 2022 | B10: 4 | C10: =POWER(Pillar1_quarterly1018[[#This Row],[A. ASSET]]^10*Pillar1_quarterly1018[[#This Row],[B. ADAPTIVE CAPACITY]],1/10) -> 1.7760168 | H10: 36 | I10: =_xlfn.FORECAST.LINEAR(Table28[[#This Row],[TIME]],Table28[Pillar1 Index],Table28[TIME]) -> 1.6835723 | J10: ='Pillar1 SOS'!$C10-'Pillar1 SOS'!$I10 -> 0.092444556 | K10: ='Pillar1 SOS'!$I10-_xlfn.STDEV.S('Pillar1 SOS'!$J$2:$J$45) -> 1.6007924 | L10: ='Pillar1 SOS'!$I10-2*_xlfn.STDEV.S('Pillar1 SOS'!$J$2:$J$45) -> 1.5180124 | M10: 9 | N10: =_xlfn.FORECAST.LINEAR(Table28[[#This Row],[TIME2]],Table28[Pillar1 Index],Table28[TIME2]) -> 1.673026 | O10: =Table28[[#This Row],[Pillar1 Index]]-Table28[[#This Row],[Pillar1 SOS2]] -> 0.10299085 | P10: =N10-_xlfn.STDEV.S(Table28[Residuals2]) -> 1.5906851 | Q10: =N10-2*_xlfn.STDEV.S(Table28[Residuals2]) -> 1.5083443
A11: 2022 | B11: 3 | C11: =POWER(Pillar1_quarterly1018[[#This Row],[A. ASSET]]^10*Pillar1_quarterly1018[[#This Row],[B. ADAPTIVE CAPACITY]],1/10) -> 1.7760168 | D11: Economic | E11: 2 | H11: 35 | I11: =_xlfn.FORECAST.LINEAR(Table28[[#This Row],[TIME]],Table28[Pillar1 Index],Table28[TIME]) -> 1.6760727 | J11: ='Pillar1 SOS'!$C11-'Pillar1 SOS'!$I11 -> 0.099944142 | K11: ='Pillar1 SOS'!$I11-_xlfn.STDEV.S('Pillar1 SOS'!$J$2:$J$45) -> 1.5932928 | L11: ='Pillar1 SOS'!$I11-2*_xlfn.STDEV.S('Pillar1 SOS'!$J$2:$J$45) -> 1.5105128 | M11: 9 | N11: =_xlfn.FORECAST.LINEAR(Table28[[#This Row],[TIME2]],Table28[Pillar1 Index],Table28[TIME2]) -> 1.673026 | O11: =Table28[[#This Row],[Pillar1 Index]]-Table28[[#This Row],[Pillar1 SOS2]] -> 0.10299085 | P11: =N11-_xlfn.STDEV.S(Table28[Residuals2]) -> 1.5906851 | Q11: =N11-2*_xlfn.STDEV.S(Table28[Residuals2]) -> 1.5083443
A12: 2022 | B12: 2 | C12: =POWER(Pillar1_quarterly1018[[#This Row],[A. ASSET]]^10*Pillar1_quarterly1018[[#This Row],[B. ADAPTIVE CAPACITY]],1/10) -> 1.7760168 | D12: Economic | E12: 2 | H12: 34 | I12: =_xlfn.FORECAST.LINEAR(Table28[[#This Row],[TIME]],Table28[Pillar1 Index],Table28[TIME]) -> 1.6685731 | J12: ='Pillar1 SOS'!$C12-'Pillar1 SOS'!$I12 -> 0.10744373 | K12: ='Pillar1 SOS'!$I12-_xlfn.STDEV.S('Pillar1 SOS'!$J$2:$J$45) -> 1.5857932 | L12: ='Pillar1 SOS'!$I12-2*_xlfn.STDEV.S('Pillar1 SOS'!$J$2:$J$45) -> 1.5030133 | M12: 9 | N12: =_xlfn.FORECAST.LINEAR(Table28[[#This Row],[TIME2]],Table28[Pillar1 Index],Table28[TIME2]) -> 1.673026 | O12: =Table28[[#This Row],[Pillar1 Index]]-Table28[[#This Row],[Pillar1 SOS2]] -> 0.10299085 | P12: =N12-_xlfn.STDEV.S(Table28[Residuals2]) -> 1.5906851 | Q12: =N12-2*_xlfn.STDEV.S(Table28[Residuals2]) -> 1.5083443
A13: 2022 | B13: 1 | C13: =POWER(Pillar1_quarterly1018[[#This Row],[A. ASSET]]^10*Pillar1_quarterly1018[[#This Row],[B. ADAPTIVE CAPACITY]],1/10) -> 1.7760168 | H13: 33 | I13: =_xlfn.FORECAST.LINEAR(Table28[[#This Row],[TIME]],Table28[Pillar1 Index],Table28[TIME]) -> 1.6610735 | J13: ='Pillar1 SOS'!$C13-'Pillar1 SOS'!$I13 -> 0.11494331 | K13: ='Pillar1 SOS'!$I13-_xlfn.STDEV.S('Pillar1 SOS'!$J$2:$J$45) -> 1.5782936 | L13: ='Pillar1 SOS'!$I13-2*_xlfn.STDEV.S('Pillar1 SOS'!$J$2:$J$45) -> 1.4955137 | M13: 9 | N13: =_xlfn.FORECAST.LINEAR(Table28[[#This Row],[TIME2]],Table28[Pillar1 Index],Table28[TIME2]) -> 1.673026 | O13: =Table28[[#This Row],[Pillar1 Index]]-Table28[[#This Row],[Pillar1 SOS2]] -> 0.10299085 | P13: =N13-_xlfn.STDEV.S(Table28[Residuals2]) -> 1.5906851 | Q13: =N13-2*_xlfn.STDEV.S(Table28[Residuals2]) -> 1.5083443
A14: 2021 | B14: 4 | C14: =POWER(Pillar1_quarterly1018[[#This Row],[A. ASSET]]^10*Pillar1_quarterly1018[[#This Row],[B. ADAPTIVE CAPACITY]],1/10) -> 1.5266729 | H14: 32 | I14: =_xlfn.FORECAST.LINEAR(Table28[[#This Row],[TIME]],Table28[Pillar1 Index],Table28[TIME]) -> 1.6535739 | J14: ='Pillar1 SOS'!$C14-'Pillar1 SOS'!$I14 -> -0.12690103 | K14: ='Pillar1 SOS'!$I14-_xlfn.STDEV.S('Pillar1 SOS'!$J$2:$J$45) -> 1.570794 | L14: ='Pillar1 SOS'!$I14-2*_xlfn.STDEV.S('Pillar1 SOS'!$J$2:$J$45) -> 1.4880141 | M14: 8 | N14: =_xlfn.FORECAST.LINEAR(Table28[[#This Row],[TIME2]],Table28[Pillar1 Index],Table28[TIME2]) -> 1.6427933 | O14: =Table28[[#This Row],[Pillar1 Index]]-Table28[[#This Row],[Pillar1 SOS2]] -> -0.11612038 | P14: =N14-_xlfn.STDEV.S(Table28[Residuals2]) -> 1.5604524 | Q14: =N14-2*_xlfn.STDEV.S(Table28[Residuals2]) -> 1.4781116
A15: 2021 | B15: 3 | C15: =POWER(Pillar1_quarterly1018[[#This Row],[A. ASSET]]^10*Pillar1_quarterly1018[[#This Row],[B. ADAPTIVE CAPACITY]],1/10) -> 1.5266729 | D15: Economic | E15: 3 | H15: 31 | I15: =_xlfn.FORECAST.LINEAR(Table28[[#This Row],[TIME]],Table28[Pillar1 Index],Table28[TIME]) -> 1.6460744 | J15: ='Pillar1 SOS'!$C15-'Pillar1 SOS'!$I15 -> -0.11940145 | K15: ='Pillar1 SOS'!$I15-_xlfn.STDEV.S('Pillar1 SOS'!$J$2:$J$45) -> 1.5632944 | L15: ='Pillar1 SOS'!$I15-2*_xlfn.STDEV.S('Pillar1 SOS'!$J$2:$J$45) -> 1.4805145 | M15: 8 | N15: =_xlfn.FORECAST.LINEAR(Table28[[#This Row],[TIME2]],Table28[Pillar1 Index],Table28[TIME2]) -> 1.6427933 | O15: =Table28[[#This Row],[Pillar1 Index]]-Table28[[#This Row],[Pillar1 SOS2]] -> -0.11612038 | P15: =N15-_xlfn.STDEV.S(Table28[Residuals2]) -> 1.5604524 | Q15: =N15-2*_xlfn.STDEV.S(Table28[Residuals2]) -> 1.4781116
A16: 2021 | B16: 2 | C16: =POWER(Pillar1_quarterly1018[[#This Row],[A. ASSET]]^10*Pillar1_quarterly1018[[#This Row],[B. ADAPTIVE CAPACITY]],1/10) -> 1.5266729 | D16: Economic | E16: 2 | H16: 30 | I16: =_xlfn.FORECAST.LINEAR(Table28[[#This Row],[TIME]],Table28[Pillar1 Index],Table28[TIME]) -> 1.6385748 | J16: ='Pillar1 SOS'!$C16-'Pillar1 SOS'!$I16 -> -0.11190186 | K16: ='Pillar1 SOS'!$I16-_xlfn.STDEV.S('Pillar1 SOS'!$J$2:$J$45) -> 1.5557948 | L16: ='Pillar1 SOS'!$I16-2*_xlfn.STDEV.S('Pillar1 SOS'!$J$2:$J$45) -> 1.4730149 | M16: 8 | N16: =_xlfn.FORECAST.LINEAR(Table28[[#This Row],[TIME2]],Table28[Pillar1 Index],Table28[TIME2]) -> 1.6427933 | O16: =Table28[[#This Row],[Pillar1 Index]]-Table28[[#This Row],[Pillar1 SOS2]] -> -0.11612038 | P16: =N16-_xlfn.STDEV.S(Table28[Residuals2]) -> 1.5604524 | Q16: =N16-2*_xlfn.STDEV.S(Table28[Residuals2]) -> 1.4781116
A17: 2021 | B17: 1 | C17: =POWER(Pillar1_quarterly1018[[#This Row],[A. ASSET]]^10*Pillar1_quarterly1018[[#This Row],[B. ADAPTIVE CAPACITY]],1/10) -> 1.5266729 | D17: Economic | E17: 2 | H17: 29 | I17: =_xlfn.FORECAST.LINEAR(Table28[[#This Row],[TIME]],Table28[Pillar1 Index],Table28[TIME]) -> 1.6310752 | J17: ='Pillar1 SOS'!$C17-'Pillar1 SOS'!$I17 -> -0.10440227 | K17: ='Pillar1 SOS'!$I17-_xlfn.STDEV.S('Pillar1 SOS'!$J$2:$J$45) -> 1.5482953 | L17: ='Pillar1 SOS'!$I17-2*_xlfn.STDEV.S('Pillar1 SOS'!$J$2:$J$45) -> 1.4655153 | M17: 8 | N17: =_xlfn.FORECAST.LINEAR(Table28[[#This Row],[TIME2]],Table28[Pillar1 Index],Table28[TIME2]) -> 1.6427933 | O17: =Table28[[#This Row],[Pillar1 Index]]-Table28[[#This Row],[Pillar1 SOS2]] -> -0.11612038 | P17: =N17-_xlfn.STDEV.S(Table28[Residuals2]) -> 1.5604524 | Q17: =N17-2*_xlfn.STDEV.S(Table28[Residuals2]) -> 1.4781116
A18: 2020 | B18: 4 | C18: =POWER(Pillar1_quarterly1018[[#This Row],[A. ASSET]]^10*Pillar1_quarterly1018[[#This Row],[B. ADAPTIVE CAPACITY]],1/10) -> 1.4682019 | D18: Environmental/Biological | E18: 1 | H18: 28 | I18: =_xlfn.FORECAST.LINEAR(Table28[[#This Row],[TIME]],Table28[Pillar1 Index],Table28[TIME]) -> 1.6235756 | J18: ='Pillar1 SOS'!$C18-'Pillar1 SOS'!$I18 -> -0.15537365 | K18: ='Pillar1 SOS'!$I18-_xlfn.STDEV.S('Pillar1 SOS'!$J$2:$J$45) -> 1.5407957 | L18: ='Pillar1 SOS'!$I18-2*_xlfn.STDEV.S('Pillar1 SOS'!$J$2:$J$45) -> 1.4580157 | M18: 7 | N18: =_xlfn.FORECAST.LINEAR(Table28[[#This Row],[TIME2]],Table28[Pillar1 Index],Table28[TIME2]) -> 1.6125606 | O18: =Table28[[#This Row],[Pillar1 Index]]-Table28[[#This Row],[Pillar1 SOS2]] -> -0.14435864 | P18: =N18-_xlfn.STDEV.S(Table28[Residuals2]) -> 1.5302197 | Q18: =N18-2*_xlfn.STDEV.S(Table28[Residuals2]) -> 1.4478789
A19: 2020 | B19: 3 | C19: =POWER(Pillar1_quarterly1018[[#This Row],[A. ASSET]]^10*Pillar1_quarterly1018[[#This Row],[B. ADAPTIVE CAPACITY]],1/10) -> 1.4682019 | D19: Political/Policy | E19: 1 | H19: 27 | I19: =_xlfn.FORECAST.LINEAR(Table28[[#This Row],[TIME]],Table28[Pillar1 Index],Table28[TIME]) -> 1.616076 | J19: ='Pillar1 SOS'!$C19-'Pillar1 SOS'!$I19 -> -0.14787407 | K19: ='Pillar1 SOS'!$I19-_xlfn.STDEV.S('Pillar1 SOS'!$J$2:$J$45) -> 1.5332961 | L19: ='Pillar1 SOS'!$I19-2*_xlfn.STDEV.S('Pillar1 SOS'!$J$2:$J$45) -> 1.4505162 | M19: 7 | N19: =_xlfn.FORECAST.LINEAR(Table28[[#This Row],[TIME2]],Table28[Pillar1 Index],Table28[TIME2]) -> 1.6125606 | O19: =Table28[[#This Row],[Pillar1 Index]]-Table28[[#This Row],[Pillar1 SOS2]] -> -0.14435864 | P19: =N19-_xlfn.STDEV.S(Table28[Residuals2]) -> 1.5302197 | Q19: =N19-2*_xlfn.STDEV.S(Table28[Residuals2]) -> 1.4478789
